Workbook
Name Slicer_Channel: #N/A
Name Slicer_Region: #N/A
Name Slicer_Sales_Rep: #N/A

Sheet Cleaned sheet
A1: Order ID | B1: Order Date | C1: Customer ID | D1: Sales Rep | E1: Region | F1: Product | G1: Category | H1: Cleaned Category | I1: Channel | J1: Quantity | K1: Unit Price (NGN) | L1: Discount (%) | M1: Status | N1: Column1 | O1: Revenue | P1: Discount Amount | Q1: Net Revenue
A2: ORD-28465 | B2: 45301 | C2: CUST-4872 | D2: Ibrahim Musa | E2: East | F2: SmartPhone X | G2: Electronics | H2: =_xlfn.XLOOKUP(F2,Analysis!A:A,Analysis!B:B,) -> Electronics | I2: In-Store | J2: 14 | K2: 220000 | L2: 0 | M2: Completed | N2: =PROPER(M2) -> Completed | O2: =SUM(Table1[[#This Row],[Quantity]]*Table1[[#This Row],[Unit Price (NGN)]]) -> 3080000 | P2: =SUM(Table1[[#This Row],[Discount (%)]]*Table1[[#This Row],[Revenue]]) -> 0 | Q2: =SUM(Table1[[#This Row],[Revenue]]-Table1[[#This Row],[Discount Amount]]) -> 3080000
A3: ORD-11553 | B3: 45559 | C3: CUST-2125 | D3: Missing Sales Rep | E3: East | F3: Laptop Pro | G3: Electronics | H3: =_xlfn.XLOOKUP(F3,Analysis!A:A,Analysis!B:B,) -> Electronics | I3: Online | J3: 17 | K3: 450000 | L3: 0.2 | M3: Completed | N3: =PROPER(M3) -> Completed | O3: =SUM(Table1[[#This Row],[Quantity]]*Table1[[#This Row],[Unit Price (NGN)]]) -> 7650000 | P3: =SUM(Table1[[#This Row],[Discount (%)]]*Table1[[#This Row],[Revenue]]) -> 1530000 | Q3: =SUM(Table1[[#This Row],[Revenue]]-Table1[[#This Row],[Discount Amount]]) -> 6120000
A4: ORD-71894 | B4: 45522 | C4: CUST-1592 | D4: Ibrahim Musa | E4: South | F4: Wireless Earbuds | G4: Accessories | H4: =_xlfn.XLOOKUP(F4,Analysis!A:A,Analysis!B:B,) -> Accessories | I4: Missing Channel | J4: 17 | K4: 35000 | L4: 0.15 | M4: Completed | N4: =PROPER(M4) -> Completed | O4: =SUM(Table1[[#This Row],[Quantity]]*Table1[[#This Row],[Unit Price (NGN)]]) -> 595000 | P4: =SUM(Table1[[#This Row],[Discount (%)]]*Table1[[#This Row],[Revenue]]) -> 89250 | Q4: =SUM(Table1[[#This Row],[Revenue]]-Table1[[#This Row],[Discount Amount]]) -> 505750
A5: ORD-25389 | B5: 45463 | C5: CUST-1904 | D5: Ngozi Adeyemi | E5: South | F5: Laptop pro | G5: Electronics | H5: =_xlfn.XLOOKUP(F5,Analysis!A:A,Analysis!B:B,) -> Electronics | I5: online | J5: 5 | K5: 450000 | L5: 0.05 | M5: Cancelled | N5: =PROPER(M5) -> Cancelled | O5: =SUM(Table1[[#This Row],[Quantity]]*Table1[[#This Row],[Unit Price (NGN)]]) -> 2250000 | P5: =SUM(Table1[[#This Row],[Discount (%)]]*Table1[[#This Row],[Revenue]]) -> 112500 | Q5: =SUM(Table1[[#This Row],[Revenue]]-Table1[[#This Row],[Discount Amount]]) -> 2137500 | U5: 100
A6: ORD-36111 | B6: 45508 | C6: CUST-1971 | D6: Ibrahim Musa | E6: North | F6: Keyboard Mech | G6: Accessories | H6: =_xlfn.XLOOKUP(F6,Analysis!A:A,Analysis!B:B,) -> Accessories | I6: Distributor | J6: 19 | K6: 28000 | L6: 0 | M6: Returned | N6: =PROPER(M6) -> Returned | O6: =SUM(Table1[[#This Row],[Quantity]]*Table1[[#This Row],[Unit Price (NGN)]]) -> 532000 | P6: =SUM(Table1[[#This Row],[Discount (%)]]*Table1[[#This Row],[Revenue]]) -> 0 | Q6: =SUM(Table1[[#This Row],[Revenue]]-Table1[[#This Row],[Discount Amount]]) -> 532000
A7: ORD-44100 | B7: 45304 | C7: CUST-4500 | D7: Kemi Adebayo | E7: North | F7: Tablet Air | G7: Electronics | H7: =_xlfn.XLOOKUP(F7,Analysis!A:A,Analysis!B:B,) -> Electronics | I7: In-Store | J7: 8 | K7: 180000 | L7: 0 | M7: Completed | N7: =PROPER(M7) -> Completed | O7: =SUM(Table1[[#This Row],[Quantity]]*Table1[[#This Row],[Unit Price (NGN)]]) -> 1440000 | P7: =SUM(Table1[[#This Row],[Discount (%)]]*Table1[[#This Row],[Revenue]]) -> 0 | Q7: =SUM(Table1[[#This Row],[Revenue]]-Table1[[#This Row],[Discount Amount]]) -> 1440000
A8: ORD-45509 | B8: 45420 | C8: CUST-1494 | D8: Ngozi Adeyemi | E8: East | F8: Laptop Pro | G8: Electronics | H8: =_xlfn.XLOOKUP(F8,Analysis!A:A,Analysis!B:B,) -> Electronics | I8: Online | J8: 18 | K8: 450000 | L8: 0.2 | M8: Completed | N8: =PROPER(M8) -> Completed | O8: =SUM(Table1[[#This Row],[Quantity]]*Table1[[#This Row],[Unit Price (NGN)]]) -> 8100000 | P8: =SUM(Table1[[#This Row],[Discount (%)]]*Table1[[#This Row],[Revenue]]) -> 1620000 | Q8: =SUM(Table1[[#This Row],[Revenue]]-Table1[[#This Row],[Discount Amount]]) -> 6480000
A9: ORD-96827 | B9: 45392 | C9: CUST-2069 | D9: Fatima Aliyu | E9: East | F9: Tablet Air | G9: Electronics | H9: =_xlfn.XLOOKUP(F9,Analysis!A:A,Analysis!B:B,) -> Electronics | I9: Online | J9: 11 | K9: 180000 | L9: 0 | M9: Completed | N9: =PROPER(M9) -> Completed | O9: =SUM(Table1[[#This Row],[Quantity]]*Table1[[#This Row],[Unit Price (NGN)]]) -> 1980000 | P9: =SUM(Table1[[#This Row],[Discount (%)]]*Table1[[#This Row],[Revenue]]) -> 0 | Q9: =SUM(Table1[[#This Row],[Revenue]]-Table1[[#This Row],[Discount Amount]]) -> 1980000
A10: ORD-52516 | B10: 45424 | C10: CUST-2535 | D10: Ibrahim Musa | E10: South | F10: Laptop Pro | G10: Electronics | H10: =_xlfn.XLOOKUP(F10,Analysis!A:A,Analysis!B:B,) -> Electronics | I10: In-Store | J10: 17 | K10: 450000 | L10: 0.05 | M10: Completed | N10: =PROPER(M10) -> Completed | O10: =SUM(Table1[[#This Row],[Quantity]]*Table1[[#This Row],[Unit Price (NGN)]]) -> 7650000 | P10: =SUM(Table1[[#This Row],[Discount (%)]]*Table1[[#This Row],[Revenue]]) -> 382500 | Q10: =SUM(Table1[[#This Row],[Revenue]]-Table1[[#This Row],[Discount Amount]]) -> 7267500
A11: ORD-99593 | B11: 45586 | C11: CUST-1700 | D11: Tunde Fashola | E11: South | F11: SmartPhone X | G11: Electronics | H11: =_xlfn.XLOOKUP(F11,Analysis!A:A,Analysis!B:B,) -> Electronics | I11: In-Store | J11: 6 | K11: 220000 | L11: 0.05 | M11: Completed | N11: =PROPER(M11) -> Completed | O11: =SUM(Table1[[#This Row],[Quantity]]*Table1[[#This Row],[Unit Price (NGN)]]) -> 1320000 | P11: =SUM(Table1[[#This Row],[Discount (%)]]*Table1[[#This Row],[Revenue]]) -> 66000 | Q11: =SUM(Table1[[#This Row],[Revenue]]-Table1[[#This Row],[Discount Amount]]) -> 1254000
A12: ORD-22240 | B12: 45606 | C12: CUST-1920 | D12: Ngozi Adeyemi | E12: South | F12: Wireless Earbuds | G12: Accessories | H12: =_xlfn.XLOOKUP(F12,Analysis!A:A,Analysis!B:B,) -> Accessories | I12: Online | J12: 2 | K12: 35000 | L12: 0 | M12: Completed | N12: =PROPER(M12) -> Completed | O12: =SUM(Table1[[#This Row],[Quantity]]*Table1[[#This Row],[Unit Price (NGN)]]) -> 70000 | P12: =SUM(Table1[[#This Row],[Discount (%)]]*Table1[[#This Row],[Revenue]]) -> 0 | Q12: =SUM(Table1[[#This Row],[Revenue]]-Table1[[#This Row],[Discount Amount]]) -> 70000
A13: ORD-68079 | B13: 45436 | C13: CUST-2707 | D13: Yemi Osinbajo | E13: South | F13: Monitor 4K | G13: Electronics | H13: =_xlfn.XLOOKUP(F13,Analysis!A:A,Analysis!B:B,) -> Electronics | I13: Online | J13: 7 | K13: 95000 | L13: 0.05 | M13: Pending | N13: =PROPER(M13) -> Pending | O13: =SUM(Table1[[#This Row],[Quantity]]*Table1[[#This Row],[Unit Price (NGN)]]) -> 665000 | P13: =SUM(Table1[[#This Row],[Discount (%)]]*Table1[[#This Row],[Revenue]]) -> 33250 | Q13: =SUM(Table1[[#This Row],[Revenue]]-Table1[[#This Row],[Discount Amount]]) -> 631750
A14: ORD-64505 | B14: 45529 | C14: CUST-3201 | D14: Ngozi Adeyemi | E14: East | F14: Webcam HD | G14: Accessories | H14: =_xlfn.XLOOKUP(F14,Analysis!A:A,Analysis!B:B,) -> Accessories | I14: In-Store | J14: 20 | K14: 22000 | L14: 0.2 | M14: Completed | N14: =PROPER(M14) -> Completed | O14: =SUM(Table1[[#This Row],[Quantity]]*Table1[[#This Row],[Unit Price (NGN)]]) -> 440000 | P14: =SUM(Table1[[#This Row],[Discount (%)]]*Table1[[#This Row],[Revenue]]) -> 88000 | Q14: =SUM(Table1[[#This Row],[Revenue]]-Table1[[#This Row],[Discount Amount]]) -> 352000
A15: ORD-66059 | B15: 45446 | C15: CUST-2641 | D15: Amaka Bello | E15: South | F15: Webcam HD | G15: Accessories | H15: =_xlfn.XLOOKUP(F15,Analysis!A:A,Analysis!B:B,) -> Accessories | I15: In-Store | J15: 16 | K15: 22000 | L15: 0 | M15: Pending | N15: =PROPER(M15) -> Pending | O15: =SUM(Table1[[#This Row],[Quantity]]*Table1[[#This Row],[Unit Price (NGN)]]) -> 352000 | P15: =SUM(Table1[[#This Row],[Discount (%)]]*Table1[[#This Row],[Revenue]]) -> 0 | Q15: =SUM(Table1[[#This Row],[Revenue]]-Table1[[#This Row],[Discount Amount]]) -> 352000
A16: ORD-99166 | B16: 45614 | C16: CUST-4075 | D16: Emeka Nwosu | E16: East | F16: SmartPhone X | G16: Electronics | H16: =_xlfn.XLOOKUP(F16,Analysis!A:A,Analysis!B:B,) -> Electronics | I16: Distributor | J16: 4 | K16: 220000 | L16: 0 | M16: Completed | N16: =PROPER(M16) -> Completed | O16: =SUM(Table1[[#This Row],[Quantity]]*Table1[[#This Row],[Unit Price (NGN)]]) -> 880000 | P16: =SUM(Table1[[#This Row],[Discount (%)]]*Table1[[#This Row],[Revenue]]) -> 0 | Q16: =SUM(Table1[[#This Row],[Revenue]]-Table1[[#This Row],[Discount Amount]]) -> 880000
A17: ORD-55193 | B17: 45648 | C17: CUST-3573 | D17: Amaka Bello | E17: East | F17: Wireless Earbuds | G17: Accessories | H17: =_xlfn.XLOOKUP(F17,Analysis!A:A,Analysis!B:B,) -> Accessories | I17: In-Store | J17: 11 | K17: 35000 | L17: 0 | M17: Completed | N17: =PROPER(M17) -> Completed | O17: =SUM(Table1[[#This Row],[Quantity]]*Table1[[#This Row],[Unit Price (NGN)]]) -> 385000 | P17: =SUM(Table1[[#This Row],[Discount (%)]]*Table1[[#This Row],[Revenue]]) -> 0 | Q17: =SUM(Table1[[#This Row],[Revenue]]-Table1[[#This Row],[Discount Amount]]) -> 385000
... A423: ORD-42725 | B423: 45637 | C423: CUST-4393 | D423: Ngozi Adeyemi | E423: East | F423: Tablet Air | G423: Electronics | H423: =_xlfn.XLOOKUP(F423,Analysis!A:A,Analysis!B:B,) -> Electronics | I423: Online | J423: 16 | K423: 180000 | L423: 0 | M423: Returned | N423: =PROPER(M423) -> Returned | O423: =SUM(Table1[[#This Row],[Quantity]]*Table1[[#This Row],[Unit Price (NGN)]]) -> 2880000 | P423: =SUM(Table1[[#This Row],[Discount (%)]]*Table1[[#This Row],[Revenue]]) -> 0 | Q423: =SUM(Table1[[#This Row],[Revenue]]-Table1[[#This Row],[Discount Amount]]) -> 2880000

Sheet Dashboard
A1: ACCESSORIES/ELECTRONICS SALES 2024
AC18: V

Sheet Analysis
A2: Product | B2: category | D2: Revenue by channel
A3: Laptop Pro | B3: Electronics | D3: Row Labels | E3: Sum of Net Revenue
A4: Keyboard Mech | B4: Accessories | D4: Distributor | E4: 133517100
A5: SmartPhone X | B5: Electronics | D5: In-Store | E5: 234164410
A6: Webcam HD | B6: Accessories | D6: Online | E6: 294607850
A7: Mouse Ergo | B7: Accessories | D7: Grand Total | E7: 662289360
A8: Monitor 4K | B8: Electronics
A9: Tablet Air | B9: Electronics | D9: Average unit price by region
A10: Wireless Earbuds | B10: Accessories | D10: Region | E10: Average unit price
D11: North | E11: =AVERAGEIF('Cleaned sheet'!E:E,D11,'Cleaned sheet'!K:K) -> 177152.55
A12: Average revenue by category | D12: South | E12: =AVERAGEIF('Cleaned sheet'!E:E,D12,'Cleaned sheet'!K:K) -> 190252.25
A13: Category | B13: Average unit price | D13: East | E13: =AVERAGEIF('Cleaned sheet'!E:E,D13,'Cleaned sheet'!K:K) -> 141015.62
A14: Accessories | B14: =AVERAGEIF('Cleaned sheet'!G:G,A14,'Cleaned sheet'!K:K) -> 25708.108 | D14: West | E14: =AVERAGEIF('Cleaned sheet'!E:E,D14,'Cleaned sheet'!K:K) -> 173285.71
A15: Electronics | B15: =AVERAGEIF('Cleaned sheet'!G:G,A15,'Cleaned sheet'!K:K) -> 279704.65
A19: KPI CARDS
A20: Total revenue | B20: Total orders | C20: AOV | D20: Return rate
A21: ='Pivot Tables'!B7 -> 662289360 | B21: ='Pivot Tables'!H11 -> 413 | C21: =SUM(A21/B21) -> 1603606.2 | D21: ='Pivot Tables'!I18 -> 0.10895884

Sheet TechBridge Sales 2024
A1: Order ID | B1: Order Date | C1: Customer ID | D1: Sales Rep | E1: Region | F1: Product | G1: Category | H1: Channel | I1: Quantity | J1: Unit Price (NGN) | K1: Discount (%) | L1: Status
A2: ORD-28465 | B2: 45566 | C2: CUST-4872 | D2: Ibrahim Musa | E2: East | F2: Smart Phone X | G2: Electronics | H2: In-Store | I2: 14 | J2: 220000 | K2: 0 | L2: Completed
A3: ORD-11553 | B3: 24/09/2024 | C3: CUST-2125 | E3: East | F3: Laptop Pro | G3: Electronics | H3: Online | I3: 17 | J3: 450000 | K3: 20 | L3: Completed
A4: ORD-71894 | B4: 18/08/2024 | C4: CUST-1592 | D4: Ibrahim Musa | E4: South | F4: Wireless Earbuds | G4: Accessories | I4: 17 | J4: 35000 | K4: 15 | L4: Completed
A5: ORD-25389 | B5: 20/06/2024 | C5: CUST-1904 | D5: Ngozi Adeyemi | E5: South | F5: Laptop pro | G5: electronics | H5: online | I5: 5 | J5: 450000 | K5: 5 | L5: Cancelled
A6: ORD-36111 | B6: 45390 | C6: CUST-1971 | D6: Ibrahim Musa | E6: North | F6: Keyboard Mech | G6: Accessories | H6: Distributor | I6: 19 | J6: 28000 | K6: 0 | L6: Returned
A7: ORD-44100 | B7: 13/01/2024 | C7: CUST-4500 | D7: Kemi Adebayo | E7: North | F7: Tablet Air | G7: Electronics | H7: In-Store | I7: 8 | J7: 180000 | K7: 0 | L7: Completed
A8: ORD-45509 | B8: 45509 | C8: CUST-1494 | D8: Ngozi Adeyemi | E8: East | F8: Laptop Pro | G8: Electronics | H8: Online | I8: 18 | J8: 450000 | K8: 20 | L8: Completed
A9: ORD-96827 | B9: 45569 | C9: CUST-2069 | D9: Fatima Aliyu | E9: East | F9: Tablet Air | G9: Electronics | H9: Online | I9: 11 | J9: 180000 | K9: 0 | L9: Completed
A10: ORD-52516 | B10: 45631 | C10: CUST-2535 | D10: Ibrahim Musa | E10: South | F10: Lap TopPro | G10: ELECTRONICS | H10: in store | I10: 17 | J10: 450000 | K10: 5 | L10: Completed
A11: ORD-99593 | B11: 21/10/2024 | C11: CUST-1700 | D11: Tunde Fashola | E11: South | F11: Smart Phone X | G11: Electronics | H11: In-Store | I11: 6 | J11: 220000 | K11: 5 | L11: Completed
A12: ORD-22240 | B12: 45576 | C12: CUST-1920 | D12: Ngozi Adeyemi | E12: South | F12: Wireless Earbuds | G12: Accessories | H12: Online | I12: 2 | J12: 35000 | K12: 0 | L12: Completed
A13: ORD-68079 | B13: 24/05/2024 | C13: CUST-2707 | D13: Yemi Osinbajo | E13: south | F13: Monitor 4K | G13: Electronics | H13: On-Line | I13: 7 | J13: 95000 | K13: 5 | L13: Pending
A14: ORD-64505 | B14: 25/08/2024 | C14: CUST-3201 | D14: Ngozi Adeyemi | E14: East | F14: Webcam HD | G14: Accessories | H14: In-Store | I14: 20 | J14: 22000 | K14: 20 | L14: Completed
A15: ORD-66059 | B15: 45357 | C15: CUST-2641 | D15: Amaka Bello | E15: South | F15: Webcam HD | G15: Accessories | H15: In-Store | I15: 16 | J15: 22000 | K15: 0 | L15: Pending
A16: ORD-99166 | B16: 18/11/2024 | C16: CUST-4075 | D16: Emeka Nwosu | E16: East | F16: Smart Phone X | G16: Electronics | H16: Distributor | I16: 4 | J16: 220000 | K16: 0 | L16: Completed
A17: ORD-55193 | B17: 22/12/2024 | C17: CUST-3573 | D17: Amaka Bello | E17: East | F17: Wireless Earbuds | G17: Accessories | H17: In-Store | I17: 11 | J17: 35000 | K17: 0 | L17: Completed
A18: ORD-26864 | B18: 45633 | C18: CUST-4255 | D18: Fatima Aliyu | E18: North | F18: Smart Phone X | G18: Electronics | H18: Distributor | I18: 5 | J18: 220000 | K18: 0 | L18: Completed
A19: ORD-50857 | B19: 21/11/2024 | C19: CUST-2529 | D19: Kemi Adebayo | E19: North | F19: Keyboard Mech | G19: Accessories | H19: Online | I19: 4 | J19: 28000 | K19: 0 | L19: Pending
A20: ORD-29198 | B20: 45566 | C20: CUST-4912 | D20: Amaka Bello | E20: East | F20: Laptop Pro | G20: Electronics | H20: Online | I20: 9 | J20: 450000 | K20: 15 | L20: Completed
A21: ORD-58629 | B21: 19/07/2024 | C21: CUST-4040 | D21: Chukwudi Eze | E21: West | F21: Webcam HD | G21: Accessories | H21: Online | I21: 16 | J21: 22000 | K21: 10 | L21: Completed
A22: ORD-51770 | B22: 21/12/2024 | C22: CUST-2373 | D22: Chukwudi Eze | E22: South | F22: Smart Phone X | G22: Electronics | H22: Online | I22: 10 | J22: 220000 | K22: 20 | L22: Completed
A23: ORD-57329 | B23: 13/03/2024 | C23: CUST-4525 | D23: Yemi Osinbajo | E23: West | F23: Monitor 4K | G23: Electronics | H23: Distributor | I23: 18 | J23: 95000 | K23: 15 | L23: Completed
A24: ORD-49467 | B24: 45393 | C24: CUST-3713 | D24: Tunde Fashola | E24: East | F24: Keyboard Mech | G24: Accessories | H24: In-Store | I24: 20 | J24: 28000 | K24: 15 | L24: Completed
A25: ORD-68515 | B25: 24/04/2024 | C25: CUST-1181 | D25: Ibrahim Musa | E25: West | F25: Laptop Pro | G25: Electronics | H25: In-Store | I25: 18 | J25: 450000 | K25: 0 | L25: Completed
A26: ORD-27987 | B26: 45601 | C26: CUST-1491 | D26: James Okafor | E26: West | F26: Laptop Pro | G26: Electronics | H26: Online | I26: 6 | J26: 450000 | K26: 0 | L26: Completed
A27: ORD-88504 | B27: 45299 | C27: CUST-1458 | D27: Fatima Aliyu | E27: East | F27: Monitor 4K | G27: Electronics | H27: Distributor | I27: 8 | J27: 95000 | K27: 0 | L27: Pending
A28: ORD-21919 | B28: 26/08/2024 | C28: CUST-1227 | D28: Kemi Adebayo | E28: South | F28: Webcam HD | G28: Accessories | H28: In-Store | I28: 14 | J28: 999999999 | K28: 5 | L28: Completed
A29: ORD-23357 | B29: 45293 | C29: CUST-1252 | D29: Ngozi Adeyemi | E29: South | F29: Tablet Air | G29: Electronics | H29: In-Store | I29: 13 | J29: 180000 | K29: 0 | L29: Completed
A30: ORD-92288 | B30: 15/07/2024 | C30: CUST-1309 | D30: Amaka Bello | E30: West | F30: Keyboard Mech | G30: Accessories | H30: In-Store | I30: 9 | J30: 28000 | K30: 15 | L30: Cancelled
A31: ORD-87820 | B31: 27/09/2024 | C31: CUST-3087 | D31: Tunde Fashola | E31: West | F31: Monitor 4K | G31: Electronics | H31: In-Store | I31: 10 | J31: 95000 | K31: 5 | L31: Completed
A32: ORD-20592 | B32: 21/06/2024 | C32: CUST-1724 | D32: Fatima Aliyu | E32: South | F32: Mouse Ergo | G32: Accessories | H32: Online | I32: 1 | J32: 18000 | K32: 5 | L32: Returned
A33: ORD-92050 | B33: 16/09/2024 | C33: CUST-1192 | D33: Fatima Aliyu | E33: South | F33: Keyboard Mech | G33: Accessories | H33: Online | I33: 17 | J33: 28000 | K33: 0 | L33: Completed
A34: ORD-21506 | B34: 45637 | C34: n | D34: Amaka Bello | E34: North | F34: Monitor 4K | G34: Electronics | H34: In-Store | I34: 10 | J34: 1 | K34: 0 | L34: Completed
A35: ORD-21970 | B35: 27/11/2024 | C35: CUST-4524 | D35: Yemi Osinbajo | E35: North | F35: Wireless Earbuds | G35: Accessories | H35: Online | I35: 9 | J35: 35000 | K35: 10 | L35: Completed
A36: ORD-28367 | B36: 45509 | C36: CUST-4341 | D36: Yemi Osinbajo | E36: East | F36: Webcam HD | G36: Accessories | H36: In-Store | I36: 20 | J36: 22000 | K36: 20 | L36: Cancelled
A37: ORD-76648 | B37: 45627 | C37: CUST-2265 | D37: Chukwudi Eze | E37: South | F37: Monitor 4K | G37: Electronics | H37: Distributor | I37: 16 | J37: 95000 | K37: 0 | L37: Pending
A38: ORD-91006 | B38: 13/10/2024 | C38: CUST-1631 | D38: Chukwudi Eze | E38: South | F38: Tablet Air | G38: Electronics | H38: In-Store | I38: 6 | J38: 180000 | K38: 15 | L38: Completed
A39: ORD-26059 | B39: 45330 | C39: CUST-1688 | D39: Yemi Osinbajo | E39: West | F39: Laptop Pro | G39: Electronics | H39: Online | I39: 16 | J39: 450000 | K39: 0 | L39: Completed
A40: ORD-16839 | B40: 18/06/2024 | C40: CUST-4826 | D40: Amaka Bello | E40: South | F40: Mouse Ergo | G40: Accessories | H40: In-Store | I40: 4 | J40: 18000 | K40: 0 | L40: Completed
...

Sheet Pivot Tables
A1: Sales rep revenue by region | D1: Revenue by sales rep | G1: Quantity & average unit price by product | L1: Revenue by product
A2: Row Labels | B2: Sum of Net Revenue | D2: Row Labels | E2: Sum of Net Revenue | G2: Row Labels | H2: Count of Order ID | I2: Sum of Quantity | J2: Average of Unit Price (NGN) | L2: Row Labels | M2: Sum of Net Revenue
A3: South | B3: 213065150 | D3: Ibrahim Musa | E3: 111935250 | G3: Laptop Pro | H3: 95 | I3: 967 | J3: 445315.79 | L3: Laptop Pro | M3: 403657500
A4: East | B4: 175019550 | D4: Fatima Aliyu | E4: 77621150 | G4: SmartPhone X | H4: 54 | I4: 491 | J4: 220000 | L4: SmartPhone X | M4: 102564000
A5: North | B5: 174104510 | D5: Tunde Fashola | E5: 75246500 | G5: Tablet Air | H5: 40 | I5: 437 | J5: 180000 | L5: Tablet Air | M5: 72756000
A6: West | B6: 100100150 | D6: Yemi Osinbajo | E6: 74782550 | G6: Monitor 4K | H6: 44 | I6: 445 | J6: 92840.932 | L6: Monitor 4K | M6: 39292010
A7: Grand Total | B7: 662289360 | D7: Ngozi Adeyemi | E7: 68802300 | G7: Wireless Earbuds | H7: 40 | I7: 444 | J7: 35000 | L7: Wireless Earbuds | M7: 14246750
D8: Grand Total | E8: 408387750 | G8: Keyboard Mech | H8: 52 | I8: 546 | J8: 28000 | L8: Keyboard Mech | M8: 14236600
A9: Row Labels | B9: Sum of Net Revenue | G9: Webcam HD | H9: 42 | I9: 460 | J9: 22000 | L9: Webcam HD | M9: 9166300
A10: Jan | B10: 42681950 | G10: Mouse Ergo | H10: 46 | I10: 397 | J10: 18000 | L10: Mouse Ergo | M10: 6370200
A11: Feb | B11: 36854500 | G11: Grand Total | H11: 413 | I11: 4187 | J11: 169680.39 | L11: Grand Total | M11: 662289360
A12: Mar | B12: 81983300
A13: Apr | B13: 65072400 | G13: Status count
A14: May | B14: 68612050 | G14: Row Labels | H14: Count of Order ID | I14: % of Total Orders | K14: Monthly revenue trend by channel
A15: Jun | B15: 46005700 | G15: Completed | H15: 265 | I15: 0.64164649 | K15: Sum of Net Revenue | L15: Column Labels
A16: Jul | B16: 84185650 | G16: Pending | H16: 56 | I16: 0.13559322 | K16: Row Labels | L16: Distributor | M16: In-Store | N16: Online | O16: Grand Total
A17: Aug | B17: 55602950 | D17: Unit sold by channel | G17: Cancelled | H17: 47 | I17: 0.11380145 | K17: Jan | L17: 3071100 | M17: 15828000 | N17: 23782850 | O17: 42681950
A18: Sep | B18: 40103500 | D18: Row Labels | E18: Sum of Quantity | G18: Returned | H18: 45 | I18: 0.10895884 | K18: Feb | L18: 2511200 | M18: 28665500 | N18: 3540300 | O18: 34717000
A19: Oct | B19: 66571050 | D19: Distributor | E19: 849 | G19: Grand Total | H19: 413 | I19: 1 | K19: Mar | L19: 35443950 | M19: 7565350 | N19: 38974000 | O19: 81983300
A20: Nov | B20: 39991710 | D20: In-Store | E20: 1652 | K20: Apr | L20: 13703400 | M20: 38762900 | N20: 12156100 | O20: 64622400
A21: Dec | B21: 34624600 | D21: Online | E21: 1686 | K21: May | L21: 8656500 | M21: 25860400 | N21: 31701150 | O21: 66218050
A22: Grand Total | B22: 662289360 | D22: Grand Total | E22: 4187 | G22: Revenue by category | K22: Jun | L22: 3519000 | M22: 14135200 | N22: 27847500 | O22: 45501700
G23: Row Labels | H23: Sum of Net Revenue | K23: Jul | L23: 18915350 | M23: 23814900 | N23: 41455400 | O23: 84185650
G24: Electronics | H24: 618269510 | K24: Aug | L24: 12545300 | M24: 12652150 | N24: 30405500 | O24: 55602950
G25: Accessories | H25: 44019850 | K25: Sep | L25: 4011500 | M25: 16778800 | N25: 19313200 | O25: 40103500
G26: Grand Total | H26: 662289360 | K26: Oct | L26: 17473500 | M26: 27884600 | N26: 21212950 | O26: 66571050
K27: Nov | L27: 10450800 | M27: 8544010 | N27: 20996900 | O27: 39991710
K28: Dec | L28: 821500 | M28: 13168600 | N28: 20634500 | O28: 34624600
K29: Grand Total | L29: 131123100 | M29: 233660410 | N29: 292020350 | O29: 656803860
